Workbook
Name aa: INDIRECT('sc chem'!$A$22)
Name aab: INDIRECT('sc chem'!$A$23)
Name aac: INDIRECT('sc chem'!$A$25)
Name aad: INDIRECT('sc chem'!$A$26)
Name aae: INDIRECT('sc chem'!$A$27)
Name aaf: INDIRECT('sc chem'!$A$28)
Name aag: INDIRECT('sc chem'!$A$29)
Name aah: INDIRECT('sc chem'!$A$30)
Name aai: INDIRECT('sc chem'!$A$31)
Name aaj: INDIRECT('sc chem'!$A$32)
Name aak: INDIRECT('sc chem'!$A$33)
Name aal: INDIRECT('sc chem'!$A$35)
Name aam: INDIRECT('sc chem'!$A$36)
Name aan: INDIRECT('sc chem'!$A$37)
Name aao: INDIRECT('sc chem'!$A$38)
Name aap: INDIRECT('sc chem'!$A$39)
Name aaq: INDIRECT('sc chem'!$A$40)
Name aar: INDIRECT('sc chem'!$A$41)
Name aas: INDIRECT('sc chem'!$A$42)
Name aat: INDIRECT('sc chem'!$A$43)
Name aau: INDIRECT('sc chem'!$A$45)
Name aav: INDIRECT('sc chem'!$A$46)
Name aaw: INDIRECT('sc chem'!$A$47)
Name aax: INDIRECT('sc chem'!$A$48)
Name aay: INDIRECT('sc chem'!$A$49)
Name aaz: INDIRECT('sc chem'!$A$50)
Name aba: INDIRECT('sc chem'!$A$51)
Name abb: INDIRECT('sc chem'!$A$52)
Name abc: INDIRECT('sc chem'!$A$53)
Name abd: INDIRECT('sc chem'!$A$55)
Name abe: INDIRECT('sc chem'!$A$56)
Name abf: INDIRECT('sc chem'!$A$57)
Name abg: INDIRECT('sc chem'!$A$58)
Name abh: INDIRECT('sc chem'!$A$59)
Name abi: INDIRECT('sc chem'!$A$60)
Name abj: INDIRECT('sc chem'!$A$61)
Name abk: INDIRECT('sc chem'!$A$62)
Name abl: INDIRECT('sc chem'!$A$63)
Name abm: INDIRECT('sc chem'!$A$65)
Name abn: INDIRECT('sc chem'!$A$66)
Name abo: INDIRECT('sc chem'!$A$67)
Name abp: INDIRECT('sc chem'!$A$68)
Name abq: INDIRECT('sc chem'!$A$69)
Name abr: INDIRECT('sc chem'!$A$70)
Name abt: INDIRECT('sc chem'!$A$71)
Name abu: INDIRECT('sc chem'!$A$72)
Name abv: INDIRECT('sc chem'!$A$73)
Name abw: INDIRECT('sc chem'!$A$75)
Name abx: INDIRECT('sc chem'!$A$76)
Name aby: INDIRECT('sc chem'!$A$77)
Name abz: INDIRECT('sc chem'!$A$78)
Name ac: INDIRECT('sc chem'!$A$16)
Name aca: INDIRECT('sc chem'!$A$79)
Name acb: INDIRECT('sc chem'!$A$81)
Name acc: INDIRECT('sc chem'!$A$82)
Name acd: INDIRECT('sc chem'!$A$83)
Name ace: INDIRECT('sc chem'!$A$84)
Name acf: INDIRECT('sc chem'!$A$80)
Name achievements: INDIRECT('sc chem'!$A$15)
Name ACHIEVES: INDIRECT('[1]3A chem '!$B$14)

Sheet control
E2: x
E3: star
E4: ticket
E5: goldenticket
E6: diamondgem

Sheet sc chem
C2: PROGRESS DASHBOARD
F3: Summary
B6: Column1 | C6: Column2 | D6: Column3 | E6: Column4
N9: data set
P10: 0.9 | Q10: =IF(K8>=P10,K8," ")
J11: MARK TO GET | K11: ACTUAL | L11: VARIANCE | P11: 0.45 | Q11: =IF(AND(M15<P10,M15>=P11),M15," ")
C12: leaderboard DASHBOARD | I12: MARK TO GET | P12: 0.1
B13: PERCENT COMPLETION | C13: NAMES | D13: current bagde | E13: RANK | F13: ACHIEVED | G13: PROGRESS | I13: MARK OBTAIN | P13: rmder
C14: TEAM ALPHA | E14: =IF(AVERAGE(E15,E16,E17,E18,E19,E20,E21,E22,E23)>5,1000,IF(AVERAGE(E15,E16,E17,E18,E19,E20,E21,E22,E23)>4,500,IF(AVERAGE(E15,E16,E17,E18,E19,E20,E21,E22,E23)>3,300,IF(AVERAGE(E15,E16,E17,E18,E19,E20,E21,E22,E23)>2,150,IF(AVERAGE(E15,E16,E17,E18,E19,E20,E21,E22,E23)=2,50,0))))) -> 0 | F14: ='RAW SCORE'!D3 -> 0
A15: =IF(MonthlyExpenses69[[#This Row],[RANK]]<3,"x",IF(MonthlyExpenses69[[#This Row],[RANK]]=3,"star",IF(MonthlyExpenses69[[#This Row],[RANK]]=4,"ticket",IF(MonthlyExpenses69[[#This Row],[RANK]]=5,"goldenticket",IF(MonthlyExpenses69[[#This Row],[RANK]]=6,"diamondgem",))))) -> x | E15: =IF(F15>2999,6,IF(F15 >1499,5,IF(F15>799,4,IF(F15>399,3,IF(F15>99,2,1))))) -> 1 | F15: ='RAW SCORE'!D4 -> 0 | G15: =REPT("|",K15/I15*100)&TEXT(K15/I15,"0%") -> 0% | I15: =IF(J15>2999,J15-1500,IF(J15>1499,J15-800,IF(J15>799,J15-400,IF(J15>399,J15-100,100)))) -> 100 | J15: =N15 -> 100 | K15: =IF(F15>2999,F15-3000,IF(F15>1499,F15-1500,IF(F15>799,F15-800,IF(F15>399,F15-400,IF(F15>99,F15-100,F15))))) -> 0 | L15: =(K15/I15)*100 -> 0 | M15: =(K15/I15)*1 -> 0 | N15: =IF(E15>5,5000,IF(E15 >4,3000,IF(E15>3,1500,IF(E15>2,800,IF(E15>1,400,100))))) -> 100 | O15: =IF(M15>=$P$10,M15," ") | P15: =IF(AND(M15<$P$10,M15>=$P$11),M15," ") | Q15: =IF(M15<$P$11,M15," ") -> 0 | R15: =MAX(1,M15)-M15 -> 1
A16: =IF(MonthlyExpenses69[[#This Row],[RANK]]<3,"x",IF(MonthlyExpenses69[[#This Row],[RANK]]=3,"star",IF(MonthlyExpenses69[[#This Row],[RANK]]=4,"ticket",IF(MonthlyExpenses69[[#This Row],[RANK]]=5,"goldenticket",IF(MonthlyExpenses69[[#This Row],[RANK]]=6,"diamondgem",))))) -> x | E16: =IF(F16>2999,6,IF(F16 >1499,5,IF(F16>799,4,IF(F16>399,3,IF(F16>99,2,1))))) -> 1 | F16: ='RAW SCORE'!D5 -> 0 | G16: =REPT("|",K16/I16*100)&TEXT(K16/I16,"0%") -> 0% | I16: =IF(J16>2999,J16-1500,IF(J16>1499,J16-800,IF(J16>799,J16-400,IF(J16>399,J16-100,100)))) -> 100 | J16: =N16 -> 100 | K16: =IF(F16>2999,F16-3000,IF(F16>1499,F16-1500,IF(F16>799,F16-800,IF(F16>399,F16-400,IF(F16>99,F16-100,F16))))) -> 0 | L16: =(K16/I16)*100 -> 0 | M16: =(K16/I16)*1 -> 0 | N16: =IF(E16>5,5000,IF(E16 >4,3000,IF(E16>3,1500,IF(E16>2,800,IF(E16>1,400,100))))) -> 100 | O16: =IF(M16>=$P$10,M16," ") | P16: =IF(AND(M16<$P$10,M16>=$P$11),M16," ") | Q16: =IF(M16<$P$11,M16," ") -> 0 | R16: =MAX(1,M16)-M16 -> 1
A17: =IF(MonthlyExpenses69[[#This Row],[RANK]]<3,"x",IF(MonthlyExpenses69[[#This Row],[RANK]]=3,"star",IF(MonthlyExpenses69[[#This Row],[RANK]]=4,"ticket",IF(MonthlyExpenses69[[#This Row],[RANK]]=5,"goldenticket",IF(MonthlyExpenses69[[#This Row],[RANK]]=6,"diamondgem",))))) -> x | E17: =IF(F17>2999,6,IF(F17 >1499,5,IF(F17>799,4,IF(F17>399,3,IF(F17>99,2,1))))) -> 1 | F17: ='RAW SCORE'!D6 -> 0 | G17: =REPT("|",K17/I17*100)&TEXT(K17/I17,"0%") -> 0% | I17: =IF(J17>2999,J17-1500,IF(J17>1499,J17-800,IF(J17>799,J17-400,IF(J17>399,J17-100,100)))) -> 100 | J17: =N17 -> 100 | K17: =IF(F17>2999,F17-3000,IF(F17>1499,F17-1500,IF(F17>799,F17-800,IF(F17>399,F17-400,IF(F17>99,F17-100,F17))))) -> 0 | L17: =(K17/I17)*100 -> 0 | M17: =(K17/I17)*1 -> 0 | N17: =IF(E17>5,5000,IF(E17 >4,3000,IF(E17>3,1500,IF(E17>2,800,IF(E17>1,400,100))))) -> 100 | O17: =IF(M17>=$P$10,M17," ") | P17: =IF(AND(M17<$P$10,M17>=$P$11),M17," ") | Q17: =IF(M17<$P$11,M17," ") -> 0 | R17: =MAX(1,M17)-M17 -> 1
A18: =IF(MonthlyExpenses69[[#This Row],[RANK]]<3,"x",IF(MonthlyExpenses69[[#This Row],[RANK]]=3,"star",IF(MonthlyExpenses69[[#This Row],[RANK]]=4,"ticket",IF(MonthlyExpenses69[[#This Row],[RANK]]=5,"goldenticket",IF(MonthlyExpenses69[[#This Row],[RANK]]=6,"diamondgem",))))) -> x | E18: =IF(F18>2999,6,IF(F18 >1499,5,IF(F18>799,4,IF(F18>399,3,IF(F18>99,2,1))))) -> 1 | F18: ='RAW SCORE'!D7 -> 0 | G18: =REPT("|",K18/I18*100)&TEXT(K18/I18,"0%") -> 0% | I18: =IF(J18>2999,J18-1500,IF(J18>1499,J18-800,IF(J18>799,J18-400,IF(J18>399,J18-100,100)))) -> 100 | J18: =N18 -> 100 | K18: =IF(F18>2999,F18-3000,IF(F18>1499,F18-1500,IF(F18>799,F18-800,IF(F18>399,F18-400,IF(F18>99,F18-100,F18))))) -> 0 | L18: =(K18/I18)*100 -> 0 | M18: =(K18/I18)*1 -> 0 | N18: =IF(E18>5,5000,IF(E18 >4,3000,IF(E18>3,1500,IF(E18>2,800,IF(E18>1,400,100))))) -> 100 | O18: =IF(M18>=$P$10,M18," ") | P18: =IF(AND(M18<$P$10,M18>=$P$11),M18," ") | Q18: =IF(M18<$P$11,M18," ") -> 0 | R18: =MAX(1,M18)-M18 -> 1
A19: =IF(MonthlyExpenses69[[#This Row],[RANK]]<3,"x",IF(MonthlyExpenses69[[#This Row],[RANK]]=3,"star",IF(MonthlyExpenses69[[#This Row],[RANK]]=4,"ticket",IF(MonthlyExpenses69[[#This Row],[RANK]]=5,"goldenticket",IF(MonthlyExpenses69[[#This Row],[RANK]]=6,"diamondgem",))))) -> x | E19: =IF(F19>2999,6,IF(F19 >1499,5,IF(F19>799,4,IF(F19>399,3,IF(F19>99,2,1))))) -> 1 | F19: ='RAW SCORE'!D8 -> 0 | G19: =REPT("|",K19/I19*100)&TEXT(K19/I19,"0%") -> 0% | I19: =IF(J19>2999,J19-1500,IF(J19>1499,J19-800,IF(J19>799,J19-400,IF(J19>399,J19-100,100)))) -> 100 | J19: =N19 -> 100 | K19: =IF(F19>2999,F19-3000,IF(F19>1499,F19-1500,IF(F19>799,F19-800,IF(F19>399,F19-400,IF(F19>99,F19-100,F19))))) -> 0 | L19: =(K19/I19)*100 -> 0 | M19: =(K19/I19)*1 -> 0 | N19: =IF(E19>5,5000,IF(E19 >4,3000,IF(E19>3,1500,IF(E19>2,800,IF(E19>1,400,100))))) -> 100 | O19: =IF(M19>=$P$10,M19," ") | P19: =IF(AND(M19<$P$10,M19>=$P$11),M19," ") | Q19: =IF(M19<$P$11,M19," ") -> 0 | R19: =MAX(1,M19)-M19 -> 1
A20: =IF(MonthlyExpenses69[[#This Row],[RANK]]<3,"x",IF(MonthlyExpenses69[[#This Row],[RANK]]=3,"star",IF(MonthlyExpenses69[[#This Row],[RANK]]=4,"ticket",IF(MonthlyExpenses69[[#This Row],[RANK]]=5,"goldenticket",IF(MonthlyExpenses69[[#This Row],[RANK]]=6,"diamondgem",))))) -> x | E20: =IF(F20>2999,6,IF(F20 >1499,5,IF(F20>799,4,IF(F20>399,3,IF(F20>99,2,1))))) -> 1 | F20: ='RAW SCORE'!D9 -> 0 | G20: =REPT("|",K20/I20*100)&TEXT(K20/I20,"0%") -> 0% | I20: =IF(J20>2999,J20-1500,IF(J20>1499,J20-800,IF(J20>799,J20-400,IF(J20>399,J20-100,100)))) -> 100 | J20: =N20 -> 100 | K20: =IF(F20>2999,F20-3000,IF(F20>1499,F20-1500,IF(F20>799,F20-800,IF(F20>399,F20-400,IF(F20>99,F20-100,F20))))) -> 0 | L20: =(K20/I20)*100 -> 0 | M20: =(K20/I20)*1 -> 0 | N20: =IF(E20>5,5000,IF(E20 >4,3000,IF(E20>3,1500,IF(E20>2,800,IF(E20>1,400,100))))) -> 100 | O20: =IF(M20>=$P$10,M20," ") | P20: =IF(AND(M20<$P$10,M20>=$P$11),M20," ") | Q20: =IF(M20<$P$11,M20," ") -> 0 | R20: =MAX(1,M20)-M20 -> 1
A21: =IF(MonthlyExpenses69[[#This Row],[RANK]]<3,"x",IF(MonthlyExpenses69[[#This Row],[RANK]]=3,"star",IF(MonthlyExpenses69[[#This Row],[RANK]]=4,"ticket",IF(MonthlyExpenses69[[#This Row],[RANK]]=5,"goldenticket",IF(MonthlyExpenses69[[#This Row],[RANK]]=6,"diamondgem",))))) -> x | E21: =IF(F21>2999,6,IF(F21 >1499,5,IF(F21>799,4,IF(F21>399,3,IF(F21>99,2,1))))) -> 1 | F21: ='RAW SCORE'!D10 -> 0 | G21: =REPT("|",K21/I21*100)&TEXT(K21/I21,"0%") -> 0% | I21: =IF(J21>2999,J21-1500,IF(J21>1499,J21-800,IF(J21>799,J21-400,IF(J21>399,J21-100,100)))) -> 100 | J21: =N21 -> 100 | K21: =IF(F21>2999,F21-3000,IF(F21>1499,F21-1500,IF(F21>799,F21-800,IF(F21>399,F21-400,IF(F21>99,F21-100,F21))))) -> 0 | L21: =(K21/I21)*100 -> 0 | M21: =(K21/I21)*1 -> 0 | N21: =IF(E21>5,5000,IF(E21 >4,3000,IF(E21>3,1500,IF(E21>2,800,IF(E21>1,400,100))))) -> 100 | O21: =IF(M21>=$P$10,M21," ") | P21: =IF(AND(M21<$P$10,M21>=$P$11),M21," ") | Q21: =IF(M21<$P$11,M21," ") -> 0 | R21: =MAX(1,M21)-M21 -> 1
A22: =IF(MonthlyExpenses69[[#This Row],[RANK]]<3,"x",IF(MonthlyExpenses69[[#This Row],[RANK]]=3,"star",IF(MonthlyExpenses69[[#This Row],[RANK]]=4,"ticket",IF(MonthlyExpenses69[[#This Row],[RANK]]=5,"goldenticket",IF(MonthlyExpenses69[[#This Row],[RANK]]=6,"diamondgem",))))) -> x | E22: =IF(F22>2999,6,IF(F22 >1499,5,IF(F22>799,4,IF(F22>399,3,IF(F22>99,2,1))))) -> 1 | F22: ='RAW SCORE'!D11 -> 0 | G22: =REPT("|",K22/I22*100)&TEXT(K22/I22,"0%") -> 0% | I22: =IF(J22>2999,J22-1500,IF(J22>1499,J22-800,IF(J22>799,J22-400,IF(J22>399,J22-100,100)))) -> 100 | J22: =N22 -> 100 | K22: =IF(F22>2999,F22-3000,IF(F22>1499,F22-1500,IF(F22>799,F22-800,IF(F22>399,F22-400,IF(F22>99,F22-100,F22))))) -> 0 | L22: =(K22/I22)*100 -> 0 | M22: =(K22/I22)*1 -> 0 | N22: =IF(E22>5,5000,IF(E22 >4,3000,IF(E22>3,1500,IF(E22>2,800,IF(E22>1,400,100))))) -> 100 | O22: =IF(M22>=$P$10,M22," ") | P22: =IF(AND(M22<$P$10,M22>=$P$11),M22," ") | Q22: =IF(M22<$P$11,M22," ") -> 0 | R22: =MAX(1,M22)-M22 -> 1
A23: =IF(MonthlyExpenses69[[#This Row],[RANK]]<3,"x",IF(MonthlyExpenses69[[#This Row],[RANK]]=3,"star",IF(MonthlyExpenses69[[#This Row],[RANK]]=4,"ticket",IF(MonthlyExpenses69[[#This Row],[RANK]]=5,"goldenticket",IF(MonthlyExpenses69[[#This Row],[RANK]]=6,"diamondgem",))))) -> x | E23: =IF(F23>2999,6,IF(F23 >1499,5,IF(F23>799,4,IF(F23>399,3,IF(F23>99,2,1))))) -> 1 | F23: ='RAW SCORE'!D12 -> 0 | G23: =REPT("|",K23/I23*100)&TEXT(K23/I23,"0%") -> 0% | I23: =IF(J23>2999,J23-1500,IF(J23>1499,J23-800,IF(J23>799,J23-400,IF(J23>399,J23-100,100)))) -> 100 | J23: =N23 -> 100 | K23: =IF(F23>2999,F23-3000,IF(F23>1499,F23-1500,IF(F23>799,F23-800,IF(F23>399,F23-400,IF(F23>99,F23-100,F23))))) -> 0 | L23: =(K23/I23)*100 -> 0 | M23: =(K23/I23)*1 -> 0 | N23: =IF(E23>5,5000,IF(E23 >4,3000,IF(E23>3,1500,IF(E23>2,800,IF(E23>1,400,100))))) -> 100 | O23: =IF(M23>=$P$10,M23," ") | P23: =IF(AND(M23<$P$10,M23>=$P$11),M23," ") | Q23: =IF(M23<$P$11,M23," ") -> 0 | R23: =MAX(1,M23)-M23 -> 1
C24: TEAM BETA | E24: =IF(AVERAGE(E25,E26,E27,E28,E29,E30,E31,E32,E33)>5,1000,IF(AVERAGE(E25,E26,E27,E28,E29,E30,E31,E32,E33)>4,500,IF(AVERAGE(E25,E26,E27,E28,E29,E30,E31,E32,E33)>3,300,IF(AVERAGE(E25,E26,E27,E28,E29,E30,E31,E32,E33)>2,150,IF(AVERAGE(E25,E26,E27,E28,E29,E30,E31,E32,E33)=2,50,0))))) -> 0 | F24: ='RAW SCORE'!D13 -> 0
A25: =IF(MonthlyExpenses69[[#This Row],[RANK]]<3,"x",IF(MonthlyExpenses69[[#This Row],[RANK]]=3,"star",IF(MonthlyExpenses69[[#This Row],[RANK]]=4,"ticket",IF(MonthlyExpenses69[[#This Row],[RANK]]=5,"goldenticket",IF(MonthlyExpenses69[[#This Row],[RANK]]=6,"diamondgem",))))) -> x | E25: =IF(F25>2999,6,IF(F25 >1499,5,IF(F25>799,4,IF(F25>399,3,IF(F25>99,2,1))))) -> 1 | F25: ='RAW SCORE'!D14 -> 0 | G25: =REPT("|",K25/I25*100)&TEXT(K25/I25,"0%") -> 0% | I25: =IF(J25>2999,J25-1500,IF(J25>1499,J25-800,IF(J25>799,J25-400,IF(J25>399,J25-100,100)))) -> 100 | J25: =N25 -> 100 | K25: =IF(F25>2999,F25-3000,IF(F25>1499,F25-1500,IF(F25>799,F25-800,IF(F25>399,F25-400,IF(F25>99,F25-100,F25))))) -> 0 | L25: =(K25/I25)*100 -> 0 | M25: =(K25/I25)*1 -> 0 | N25: =IF(E25>5,5000,IF(E25 >4,3000,IF(E25>3,1500,IF(E25>2,800,IF(E25>1,400,100))))) -> 100 | O25: =IF(M25>=$P$10,M25," ") | P25: =IF(AND(M25<$P$10,M25>=$P$11),M25," ") | Q25: =IF(M25<$P$11,M25," ") -> 0 | R25: =MAX(1,M25)-M25 -> 1
A26: =IF(MonthlyExpenses69[[#This Row],[RANK]]<3,"x",IF(MonthlyExpenses69[[#This Row],[RANK]]=3,"star",IF(MonthlyExpenses69[[#This Row],[RANK]]=4,"ticket",IF(MonthlyExpenses69[[#This Row],[RANK]]=5,"goldenticket",IF(MonthlyExpenses69[[#This Row],[RANK]]=6,"diamondgem",))))) -> x | E26: =IF(F26>2999,6,IF(F26 >1499,5,IF(F26>799,4,IF(F26>399,3,IF(F26>99,2,1))))) -> 1 | F26: ='RAW SCORE'!D15 -> 0 | G26: =REPT("|",K26/I26*100)&TEXT(K26/I26,"0%") -> 0% | I26: =IF(J26>2999,J26-1500,IF(J26>1499,J26-800,IF(J26>799,J26-400,IF(J26>399,J26-100,100)))) -> 100 | J26: =N26 -> 100 | K26: =IF(F26>2999,F26-3000,IF(F26>1499,F26-1500,IF(F26>799,F26-800,IF(F26>399,F26-400,IF(F26>99,F26-100,F26))))) -> 0 | L26: =(K26/I26)*100 -> 0 | M26: =(K26/I26)*1 -> 0 | N26: =IF(E26>5,5000,IF(E26 >4,3000,IF(E26>3,1500,IF(E26>2,800,IF(E26>1,400,100))))) -> 100 | O26: =IF(M26>=$P$10,M26," ") | P26: =IF(AND(M26<$P$10,M26>=$P$11),M26," ") | Q26: =IF(M26<$P$11,M26," ") -> 0 | R26: =MAX(1,M26)-M26 -> 1
A27: =IF(MonthlyExpenses69[[#This Row],[RANK]]<3,"x",IF(MonthlyExpenses69[[#This Row],[RANK]]=3,"star",IF(MonthlyExpenses69[[#This Row],[RANK]]=4,"ticket",IF(MonthlyExpenses69[[#This Row],[RANK]]=5,"goldenticket",IF(MonthlyExpenses69[[#This Row],[RANK]]=6,"diamondgem",))))) -> x | E27: =IF(F27>2999,6,IF(F27 >1499,5,IF(F27>799,4,IF(F27>399,3,IF(F27>99,2,1))))) -> 1 | F27: ='RAW SCORE'!D16 -> 0 | G27: =REPT("|",K27/I27*100)&TEXT(K27/I27,"0%") -> 0% | I27: =IF(J27>2999,J27-1500,IF(J27>1499,J27-800,IF(J27>799,J27-400,IF(J27>399,J27-100,100)))) -> 100 | J27: =N27 -> 100 | K27: =IF(F27>2999,F27-3000,IF(F27>1499,F27-1500,IF(F27>799,F27-800,IF(F27>399,F27-400,IF(F27>99,F27-100,F27))))) -> 0 | L27: =(K27/I27)*100 -> 0 | M27: =(K27/I27)*1 -> 0 | N27: =IF(E27>5,5000,IF(E27 >4,3000,IF(E27>3,1500,IF(E27>2,800,IF(E27>1,400,100))))) -> 100 | O27: =IF(M27>=$P$10,M27," ") | P27: =IF(AND(M27<$P$10,M27>=$P$11),M27," ") | Q27: =IF(M27<$P$11,M27," ") -> 0 | R27: =MAX(1,M27)-M27 -> 1
A28: =IF(MonthlyExpenses69[[#This Row],[RANK]]<3,"x",IF(MonthlyExpenses69[[#This Row],[RANK]]=3,"star",IF(MonthlyExpenses69[[#This Row],[RANK]]=4,"ticket",IF(MonthlyExpenses69[[#This Row],[RANK]]=5,"goldenticket",IF(MonthlyExpenses69[[#This Row],[RANK]]=6,"diamondgem",))))) -> x | E28: =IF(F28>2999,6,IF(F28 >1499,5,IF(F28>799,4,IF(F28>399,3,IF(F28>99,2,1))))) -> 1 | F28: ='RAW SCORE'!D17 -> 0 | G28: =REPT("|",K28/I28*100)&TEXT(K28/I28,"0%") -> 0% | I28: =IF(J28>2999,J28-1500,IF(J28>1499,J28-800,IF(J28>799,J28-400,IF(J28>399,J28-100,100)))) -> 100 | J28: =N28 -> 100 | K28: =IF(F28>2999,F28-3000,IF(F28>1499,F28-1500,IF(F28>799,F28-800,IF(F28>399,F28-400,IF(F28>99,F28-100,F28))))) -> 0 | L28: =(K28/I28)*100 -> 0 | M28: =(K28/I28)*1 -> 0 | N28: =IF(E28>5,5000,IF(E28 >4,3000,IF(E28>3,1500,IF(E28>2,800,IF(E28>1,400,100))))) -> 100 | O28: =IF(M28>=$P$10,M28," ") | P28: =IF(AND(M28<$P$10,M28>=$P$11),M28," ") | Q28: =IF(M28<$P$11,M28," ") -> 0 | R28: =MAX(1,M28)-M28 -> 1
A29: =IF(MonthlyExpenses69[[#This Row],[RANK]]<3,"x",IF(MonthlyExpenses69[[#This Row],[RANK]]=3,"star",IF(MonthlyExpenses69[[#This Row],[RANK]]=4,"ticket",IF(MonthlyExpenses69[[#This Row],[RANK]]=5,"goldenticket",IF(MonthlyExpenses69[[#This Row],[RANK]]=6,"diamondgem",))))) -> x | E29: =IF(F29>2999,6,IF(F29 >1499,5,IF(F29>799,4,IF(F29>399,3,IF(F29>99,2,1))))) -> 1 | F29: ='RAW SCORE'!D18 -> 0 | G29: =REPT("|",K29/I29*100)&TEXT(K29/I29,"0%") -> 0% | I29: =IF(J29>2999,J29-1500,IF(J29>1499,J29-800,IF(J29>799,J29-400,IF(J29>399,J29-100,100)))) -> 100 | J29: =N29 -> 100 | K29: =IF(F29>2999,F29-3000,IF(F29>1499,F29-1500,IF(F29>799,F29-800,IF(F29>399,F29-400,IF(F29>99,F29-100,F29))))) -> 0 | L29: =(K29/I29)*100 -> 0 | M29: =(K29/I29)*1 -> 0 | N29: =IF(E29>5,5000,IF(E29 >4,3000,IF(E29>3,1500,IF(E29>2,800,IF(E29>1,400,100))))) -> 100 | O29: =IF(M29>=$P$10,M29," ") | P29: =IF(AND(M29<$P$10,M29>=$P$11),M29," ") | Q29: =IF(M29<$P$11,M29," ") -> 0 | R29: =MAX(1,M29)-M29 -> 1
A30: =IF(MonthlyExpenses69[[#This Row],[RANK]]<3,"x",IF(MonthlyExpenses69[[#This Row],[RANK]]=3,"star",IF(MonthlyExpenses69[[#This Row],[RANK]]=4,"ticket",IF(MonthlyExpenses69[[#This Row],[RANK]]=5,"goldenticket",IF(MonthlyExpenses69[[#This Row],[RANK]]=6,"diamondgem",))))) -> x | E30: =IF(F30>2999,6,IF(F30 >1499,5,IF(F30>799,4,IF(F30>399,3,IF(F30>99,2,1))))) -> 1 | F30: ='RAW SCORE'!D19 -> 0 | G30: =REPT("|",K30/I30*100)&TEXT(K30/I30,"0%") -> 0% | I30: =IF(J30>2999,J30-1500,IF(J30>1499,J30-800,IF(J30>799,J30-400,IF(J30>399,J30-100,100)))) -> 100 | J30: =N30 -> 100 | K30: =IF(F30>2999,F30-3000,IF(F30>1499,F30-1500,IF(F30>799,F30-800,IF(F30>399,F30-400,IF(F30>99,F30-100,F30))))) -> 0 | L30: =(K30/I30)*100 -> 0 | M30: =(K30/I30)*1 -> 0 | N30: =IF(E30>5,5000,IF(E30 >4,3000,IF(E30>3,1500,IF(E30>2,800,IF(E30>1,400,100))))) -> 100 | O30: =IF(M30>=$P$10,M30," ") | P30: =IF(AND(M30<$P$10,M30>=$P$11),M30," ") | Q30: =IF(M30<$P$11,M30," ") -> 0 | R30: =MAX(1,M30)-M30 -> 1
A31: =IF(MonthlyExpenses69[[#This Row],[RANK]]<3,"x",IF(MonthlyExpenses69[[#This Row],[RANK]]=3,"star",IF(MonthlyExpenses69[[#This Row],[RANK]]=4,"ticket",IF(MonthlyExpenses69[[#This Row],[RANK]]=5,"goldenticket",IF(MonthlyExpenses69[[#This Row],[RANK]]=6,"diamondgem",))))) -> x | E31: =IF(F31>2999,6,IF(F31 >1499,5,IF(F31>799,4,IF(F31>399,3,IF(F31>99,2,1))))) -> 1 | F31: ='RAW SCORE'!D20 -> 0 | G31: =REPT("|",K31/I31*100)&TEXT(K31/I31,"0%") -> 0% | I31: =IF(J31>2999,J31-1500,IF(J31>1499,J31-800,IF(J31>799,J31-400,IF(J31>399,J31-100,100)))) -> 100 | J31: =N31 -> 100 | K31: =IF(F31>2999,F31-3000,IF(F31>1499,F31-1500,IF(F31>799,F31-800,IF(F31>399,F31-400,IF(F31>99,F31-100,F31))))) -> 0 | L31: =(K31/I31)*100 -> 0 | M31: =(K31/I31)*1 -> 0 | N31: =IF(E31>5,5000,IF(E31 >4,3000,IF(E31>3,1500,IF(E31>2,800,IF(E31>1,400,100))))) -> 100 | O31: =IF(M31>=$P$10,M31," ") | P31: =IF(AND(M31<$P$10,M31>=$P$11),M31," ") | Q31: =IF(M31<$P$11,M31," ") -> 0 | R31: =MAX(1,M31)-M31 -> 1
A32: =IF(MonthlyExpenses69[[#This Row],[RANK]]<3,"x",IF(MonthlyExpenses69[[#This Row],[RANK]]=3,"star",IF(MonthlyExpenses69[[#This Row],[RANK]]=4,"ticket",IF(MonthlyExpenses69[[#This Row],[RANK]]=5,"goldenticket",IF(MonthlyExpenses69[[#This Row],[RANK]]=6,"diamondgem",))))) -> x | E32: =IF(F32>2999,6,IF(F32 >1499,5,IF(F32>799,4,IF(F32>399,3,IF(F32>99,2,1))))) -> 1 | F32: ='RAW SCORE'!D21 -> 0 | G32: =REPT("|",K32/I32*100)&TEXT(K32/I32,"0%") -> 0% | I32: =IF(J32>2999,J32-1500,IF(J32>1499,J32-800,IF(J32>799,J32-400,IF(J32>399,J32-100,100)))) -> 100 | J32: =N32 -> 100 | K32: =IF(F32>2999,F32-3000,IF(F32>1499,F32-1500,IF(F32>799,F32-800,IF(F32>399,F32-400,IF(F32>99,F32-100,F32))))) -> 0 | L32: =(K32/I32)*100 -> 0 | M32: =(K32/I32)*1 -> 0 | N32: =IF(E32>5,5000,IF(E32 >4,3000,IF(E32>3,1500,IF(E32>2,800,IF(E32>1,400,100))))) -> 100 | O32: =IF(M32>=$P$10,M32," ") | P32: =IF(AND(M32<$P$10,M32>=$P$11),M32," ") | Q32: =IF(M32<$P$11,M32," ") -> 0 | R32: =MAX(1,M32)-M32 -> 1
A33: =IF(MonthlyExpenses69[[#This Row],[RANK]]<3,"x",IF(MonthlyExpenses69[[#This Row],[RANK]]=3,"star",IF(MonthlyExpenses69[[#This Row],[RANK]]=4,"ticket",IF(MonthlyExpenses69[[#This Row],[RANK]]=5,"goldenticket",IF(MonthlyExpenses69[[#This Row],[RANK]]=6,"diamondgem",))))) -> x | E33: =IF(F33>2999,6,IF(F33 >1499,5,IF(F33>799,4,IF(F33>399,3,IF(F33>99,2,1))))) -> 1 | F33: ='RAW SCORE'!D22 -> 0 | G33: =REPT("|",K33/I33*100)&TEXT(K33/I33,"0%") -> 0% | I33: =IF(J33>2999,J33-1500,IF(J33>1499,J33-800,IF(J33>799,J33-400,IF(J33>399,J33-100,100)))) -> 100 | J33: =N33 -> 100 | K33: =IF(F33>2999,F33-3000,IF(F33>1499,F33-1500,IF(F33>799,F33-800,IF(F33>399,F33-400,IF(F33>99,F33-100,F33))))) -> 0 | L33: =(K33/I33)*100 -> 0 | M33: =(K33/I33)*1 -> 0 | N33: =IF(E33>5,5000,IF(E33 >4,3000,IF(E33>3,1500,IF(E33>2,800,IF(E33>1,400,100))))) -> 100 | O33: =IF(M33>=$P$10,M33," ") | P33: =IF(AND(M33<$P$10,M33>=$P$11),M33," ") | Q33: =IF(M33<$P$11,M33," ") -> 0 | R33: =MAX(1,M33)-M33 -> 1
C34: TEAM GAMMA | E34: =IF(AVERAGE(E35,E36,E37,E38,E39,E40,E41,E42,E43)>5,1000,IF(AVERAGE(E35,E36,E37,E38,E39,E40,E41,E42,E43)>4,500,IF(AVERAGE(E35,E36,E37,E38,E39,E40,E41,E42,E43)>3,300,IF(AVERAGE(E35,E36,E37,E38,E39,E40,E41,E42,E43)>2,150,IF(AVERAGE(E35,E36,E37,E38,E39,E40,E41,E42,E43)=2,50,0))))) -> 0 | F34: ='RAW SCORE'!D23 -> 0
A35: =IF(MonthlyExpenses69[[#This Row],[RANK]]<3,"x",IF(MonthlyExpenses69[[#This Row],[RANK]]=3,"star",IF(MonthlyExpenses69[[#This Row],[RANK]]=4,"ticket",IF(MonthlyExpenses69[[#This Row],[RANK]]=5,"goldenticket",IF(MonthlyExpenses69[[#This Row],[RANK]]=6,"diamondgem",))))) -> x | E35: =IF(F35>2999,6,IF(F35 >1499,5,IF(F35>799,4,IF(F35>399,3,IF(F35>99,2,1))))) -> 1 | F35: ='RAW SCORE'!D24 -> 0 | G35: =REPT("|",K35/I35*100)&TEXT(K35/I35,"0%") -> 0% | I35: =IF(J35>2999,J35-1500,IF(J35>1499,J35-800,IF(J35>799,J35-400,IF(J35>399,J35-100,100)))) -> 100 | J35: =N35 -> 100 | K35: =IF(F35>2999,F35-3000,IF(F35>1499,F35-1500,IF(F35>799,F35-800,IF(F35>399,F35-400,IF(F35>99,F35-100,F35))))) -> 0 | L35: =(K35/I35)*100 -> 0 | M35: =(K35/I35)*1 -> 0 | N35: =IF(E35>5,5000,IF(E35 >4,3000,IF(E35>3,1500,IF(E35>2,800,IF(E35>1,400,100))))) -> 100 | O35: =IF(M35>=$P$10,M35," ") | P35: =IF(AND(M35<$P$10,M35>=$P$11),M35," ") | Q35: =IF(M35<$P$11,M35," ") -> 0 | R35: =MAX(1,M35)-M35 -> 1
A36: =IF(MonthlyExpenses69[[#This Row],[RANK]]<3,"x",IF(MonthlyExpenses69[[#This Row],[RANK]]=3,"star",IF(MonthlyExpenses69[[#This Row],[RANK]]=4,"ticket",IF(MonthlyExpenses69[[#This Row],[RANK]]=5,"goldenticket",IF(MonthlyExpenses69[[#This Row],[RANK]]=6,"diamondgem",))))) -> x | E36: =IF(F36>2999,6,IF(F36 >1499,5,IF(F36>799,4,IF(F36>399,3,IF(F36>99,2,1))))) -> 1 | F36: ='RAW SCORE'!D25 -> 0 | G36: =REPT("|",K36/I36*100)&TEXT(K36/I36,"0%") -> 0% | I36: =IF(J36>2999,J36-1500,IF(J36>1499,J36-800,IF(J36>799,J36-400,IF(J36>399,J36-100,100)))) -> 100 | J36: =N36 -> 100 | K36: =IF(F36>2999,F36-3000,IF(F36>1499,F36-1500,IF(F36>799,F36-800,IF(F36>399,F36-400,IF(F36>99,F36-100,F36))))) -> 0 | L36: =(K36/I36)*100 -> 0 | M36: =(K36/I36)*1 -> 0 | N36: =IF(E36>5,5000,IF(E36 >4,3000,IF(E36>3,1500,IF(E36>2,800,IF(E36>1,400,100))))) -> 100 | O36: =IF(M36>=$P$10,M36," ") | P36: =IF(AND(M36<$P$10,M36>=$P$11),M36," ") | Q36: =IF(M36<$P$11,M36," ") -> 0 | R36: =MAX(1,M36)-M36 -> 1
A37: =IF(MonthlyExpenses69[[#This Row],[RANK]]<3,"x",IF(MonthlyExpenses69[[#This Row],[RANK]]=3,"star",IF(MonthlyExpenses69[[#This Row],[RANK]]=4,"ticket",IF(MonthlyExpenses69[[#This Row],[RANK]]=5,"goldenticket",IF(MonthlyExpenses69[[#This Row],[RANK]]=6,"diamondgem",))))) -> x | E37: =IF(F37>2999,6,IF(F37 >1499,5,IF(F37>799,4,IF(F37>399,3,IF(F37>99,2,1))))) -> 1 | F37: ='RAW SCORE'!D26 -> 0 | G37: =REPT("|",K37/I37*100)&TEXT(K37/I37,"0%") -> 0% | I37: =IF(J37>2999,J37-1500,IF(J37>1499,J37-800,IF(J37>799,J37-400,IF(J37>399,J37-100,100)))) -> 100 | J37: =N37 -> 100 | K37: =IF(F37>2999,F37-3000,IF(F37>1499,F37-1500,IF(F37>799,F37-800,IF(F37>399,F37-400,IF(F37>99,F37-100,F37))))) -> 0 | L37: =(K37/I37)*100 -> 0 | M37: =(K37/I37)*1 -> 0 | N37: =IF(E37>5,5000,IF(E37 >4,3000,IF(E37>3,1500,IF(E37>2,800,IF(E37>1,400,100))))) -> 100 | O37: =IF(M37>=$P$10,M37," ") | P37: =IF(AND(M37<$P$10,M37>=$P$11),M37," ") | Q37: =IF(M37<$P$11,M37," ") -> 0 | R37: =MAX(1,M37)-M37 -> 1
A38: =IF(MonthlyExpenses69[[#This Row],[RANK]]<3,"x",IF(MonthlyExpenses69[[#This Row],[RANK]]=3,"star",IF(MonthlyExpenses69[[#This Row],[RANK]]=4,"ticket",IF(MonthlyExpenses69[[#This Row],[RANK]]=5,"goldenticket",IF(MonthlyExpenses69[[#This Row],[RANK]]=6,"diamondgem",))))) -> x | E38: =IF(F38>2999,6,IF(F38 >1499,5,IF(F38>799,4,IF(F38>399,3,IF(F38>99,2,1))))) -> 1 | F38: ='RAW SCORE'!D27 -> 0 | G38: =REPT("|",K38/I38*100)&TEXT(K38/I38,"0%") -> 0% | I38: =IF(J38>2999,J38-1500,IF(J38>1499,J38-800,IF(J38>799,J38-400,IF(J38>399,J38-100,100)))) -> 100 | J38: =N38 -> 100 | K38: =IF(F38>2999,F38-3000,IF(F38>1499,F38-1500,IF(F38>799,F38-800,IF(F38>399,F38-400,IF(F38>99,F38-100,F38))))) -> 0 | L38: =(K38/I38)*100 -> 0 | M38: =(K38/I38)*1 -> 0 | N38: =IF(E38>5,5000,IF(E38 >4,3000,IF(E38>3,1500,IF(E38>2,800,IF(E38>1,400,100))))) -> 100 | O38: =IF(M38>=$P$10,M38," ") | P38: =IF(AND(M38<$P$10,M38>=$P$11),M38," ") | Q38: =IF(M38<$P$11,M38," ") -> 0 | R38: =MAX(1,M38)-M38 -> 1
A39: =IF(MonthlyExpenses69[[#This Row],[RANK]]<3,"x",IF(MonthlyExpenses69[[#This Row],[RANK]]=3,"star",IF(MonthlyExpenses69[[#This Row],[RANK]]=4,"ticket",IF(MonthlyExpenses69[[#This Row],[RANK]]=5,"goldenticket",IF(MonthlyExpenses69[[#This Row],[RANK]]=6,"diamondgem",))))) -> x | E39: =IF(F39>2999,6,IF(F39 >1499,5,IF(F39>799,4,IF(F39>399,3,IF(F39>99,2,1))))) -> 1 | F39: ='RAW SCORE'!D28 -> 0 | G39: =REPT("|",K39/I39*100)&TEXT(K39/I39,"0%") -> 0% | I39: =IF(J39>2999,J39-1500,IF(J39>1499,J39-800,IF(J39>799,J39-400,IF(J39>399,J39-100,100)))) -> 100 | J39: =N39 -> 100 | K39: =IF(F39>2999,F39-3000,IF(F39>1499,F39-1500,IF(F39>799,F39-800,IF(F39>399,F39-400,IF(F39>99,F39-100,F39))))) -> 0 | L39: =(K39/I39)*100 -> 0 | M39: =(K39/I39)*1 -> 0 | N39: =IF(E39>5,5000,IF(E39 >4,3000,IF(E39>3,1500,IF(E39>2,800,IF(E39>1,400,100))))) -> 100 | O39: =IF(M39>=$P$10,M39," ") | P39: =IF(AND(M39<$P$10,M39>=$P$11),M39," ") | Q39: =IF(M39<$P$11,M39," ") -> 0 | R39: =MAX(1,M39)-M39 -> 1
A40: =IF(MonthlyExpenses69[[#This Row],[RANK]]<3,"x",IF(MonthlyExpenses69[[#This Row],[RANK]]=3,"star",IF(MonthlyExpenses69[[#This Row],[RANK]]=4,"ticket",IF(MonthlyExpenses69[[#This Row],[RANK]]=5,"goldenticket",IF(MonthlyExpenses69[[#This Row],[RANK]]=6,"diamondgem",))))) -> x | E40: =IF(F40>2999,6,IF(F40 >1499,5,IF(F40>799,4,IF(F40>399,3,IF(F40>99,2,1))))) -> 1 | F40: ='RAW SCORE'!D29 -> 0 | G40: =REPT("|",K40/I40*100)&TEXT(K40/I40,"0%") -> 0% | I40: =IF(J40>2999,J40-1500,IF(J40>1499,J40-800,IF(J40>799,J40-400,IF(J40>399,J40-100,100)))) -> 100 | J40: =N40 -> 100 | K40: =IF(F40>2999,F40-3000,IF(F40>1499,F40-1500,IF(F40>799,F40-800,IF(F40>399,F40-400,IF(F40>99,F40-100,F40))))) -> 0 | L40: =(K40/I40)*100 -> 0 | M40: =(K40/I40)*1 -> 0 | N40: =IF(E40>5,5000,IF(E40 >4,3000,IF(E40>3,1500,IF(E40>2,800,IF(E40>1,400,100))))) -> 100 | O40: =IF(M40>=$P$10,M40," ") | P40: =IF(AND(M40<$P$10,M40>=$P$11),M40," ") | Q40: =IF(M40<$P$11,M40," ") -> 0 | R40: =MAX(1,M40)-M40 -> 1
A41: =IF(MonthlyExpenses69[[#This Row],[RANK]]<3,"x",IF(MonthlyExpenses69[[#This Row],[RANK]]=3,"star",IF(MonthlyExpenses69[[#This Row],[RANK]]=4,"ticket",IF(MonthlyExpenses69[[#This Row],[RANK]]=5,"goldenticket",IF(MonthlyExpenses69[[#This Row],[RANK]]=6,"diamondgem",))))) -> x | E41: =IF(F41>2999,6,IF(F41 >1499,5,IF(F41>799,4,IF(F41>399,3,IF(F41>99,2,1))))) -> 1 | F41: ='RAW SCORE'!D30 -> 0 | G41: =REPT("|",K41/I41*100)&TEXT(K41/I41,"0%") -> 0% | I41: =IF(J41>2999,J41-1500,IF(J41>1499,J41-800,IF(J41>799,J41-400,IF(J41>399,J41-100,100)))) -> 100 | J41: =N41 -> 100 | K41: =IF(F41>2999,F41-3000,IF(F41>1499,F41-1500,IF(F41>799,F41-800,IF(F41>399,F41-400,IF(F41>99,F41-100,F41))))) -> 0 | L41: =(K41/I41)*100 -> 0 | M41: =(K41/I41)*1 -> 0 | N41: =IF(E41>5,5000,IF(E41 >4,3000,IF(E41>3,1500,IF(E41>2,800,IF(E41>1,400,100))))) -> 100 | O41: =IF(M41>=$P$10,M41," ") | P41: =IF(AND(M41<$P$10,M41>=$P$11),M41," ") | Q41: =IF(M41<$P$11,M41," ") -> 0 | R41: =MAX(1,M41)-M41 -> 1
A42: =IF(MonthlyExpenses69[[#This Row],[RANK]]<3,"x",IF(MonthlyExpenses69[[#This Row],[RANK]]=3,"star",IF(MonthlyExpenses69[[#This Row],[RANK]]=4,"ticket",IF(MonthlyExpenses69[[#This Row],[RANK]]=5,"goldenticket",IF(MonthlyExpenses69[[#This Row],[RANK]]=6,"diamondgem",))))) -> x | E42: =IF(F42>2999,6,IF(F42 >1499,5,IF(F42>799,4,IF(F42>399,3,IF(F42>99,2,1))))) -> 1 | F42: ='RAW SCORE'!D31 -> 0 | G42: =REPT("|",K42/I42*100)&TEXT(K42/I42,"0%") -> 0% | I42: =IF(J42>2999,J42-1500,IF(J42>1499,J42-800,IF(J42>799,J42-400,IF(J42>399,J42-100,100)))) -> 100 | J42: =N42 -> 100 | K42: =IF(F42>2999,F42-3000,IF(F42>1499,F42-1500,IF(F42>799,F42-800,IF(F42>399,F42-400,IF(F42>99,F42-100,F42))))) -> 0 | L42: =(K42/I42)*100 -> 0 | M42: =(K42/I42)*1 -> 0 | N42: =IF(E42>5,5000,IF(E42 >4,3000,IF(E42>3,1500,IF(E42>2,800,IF(E42>1,400,100))))) -> 100 | O42: =IF(M42>=$P$10,M42," ") | P42: =IF(AND(M42<$P$10,M42>=$P$11),M42," ") | Q42: =IF(M42<$P$11,M42," ") -> 0 | R42: =MAX(1,M42)-M42 -> 1
A43: =IF(MonthlyExpenses69[[#This Row],[RANK]]<3,"x",IF(MonthlyExpenses69[[#This Row],[RANK]]=3,"star",IF(MonthlyExpenses69[[#This Row],[RANK]]=4,"ticket",IF(MonthlyExpenses69[[#This Row],[RANK]]=5,"goldenticket",IF(MonthlyExpenses69[[#This Row],[RANK]]=6,"diamondgem",))))) -> x | E43: =IF(F43>2999,6,IF(F43 >1499,5,IF(F43>799,4,IF(F43>399,3,IF(F43>99,2,1))))) -> 1 | F43: ='RAW SCORE'!D32 -> 0 | G43: =REPT("|",K43/I43*100)&TEXT(K43/I43,"0%") -> 0% | I43: =IF(J43>2999,J43-1500,IF(J43>1499,J43-800,IF(J43>799,J43-400,IF(J43>399,J43-100,100)))) -> 100 | J43: =N43 -> 100 | K43: =IF(F43>2999,F43-3000,IF(F43>1499,F43-1500,IF(F43>799,F43-800,IF(F43>399,F43-400,IF(F43>99,F43-100,F43))))) -> 0 | L43: =(K43/I43)*100 -> 0 | M43: =(K43/I43)*1 -> 0 | N43: =IF(E43>5,5000,IF(E43 >4,3000,IF(E43>3,1500,IF(E43>2,800,IF(E43>1,400,100))))) -> 100 | O43: =IF(M43>=$P$10,M43," ") | P43: =IF(AND(M43<$P$10,M43>=$P$11),M43," ") | Q43: =IF(M43<$P$11,M43," ") -> 0 | R43: =MAX(1,M43)-M43 -> 1
C44: TEAM DELTA | E44: =IF(AVERAGE(E45,E46,E47,E48,E49,E50,E51,E52,E53)>5,1000,IF(AVERAGE(E45,E46,E47,E48,E49,E50,E51,E52,E53)>4,500,IF(AVERAGE(E45,E46,E47,E48,E49,E50,E51,E52,E53)>3,300,IF(AVERAGE(E45,E46,E47,E48,E49,E50,E51,E52,E53)>2,150,IF(AVERAGE(E45,E46,E47,E48,E49,E50,E51,E52,E53)=2,50,0))))) -> 0 | F44: ='RAW SCORE'!D33 -> 0
A45: =IF(MonthlyExpenses69[[#This Row],[RANK]]<3,"x",IF(MonthlyExpenses69[[#This Row],[RANK]]=3,"star",IF(MonthlyExpenses69[[#This Row],[RANK]]=4,"ticket",IF(MonthlyExpenses69[[#This Row],[RANK]]=5,"goldenticket",IF(MonthlyExpenses69[[#This Row],[RANK]]=6,"diamondgem",))))) -> x | E45: =IF(F45>2999,6,IF(F45 >1499,5,IF(F45>799,4,IF(F45>399,3,IF(F45>99,2,1))))) -> 1 | F45: ='RAW SCORE'!D34 -> 0 | G45: =REPT("|",K45/I45*100)&TEXT(K45/I45,"0%") -> 0% | I45: =IF(J45>2999,J45-1500,IF(J45>1499,J45-800,IF(J45>799,J45-400,IF(J45>399,J45-100,100)))) -> 100 | J45: =N45 -> 100 | K45: =IF(F45>2999,F45-3000,IF(F45>1499,F45-1500,IF(F45>799,F45-800,IF(F45>399,F45-400,IF(F45>99,F45-100,F45))))) -> 0 | L45: =(K45/I45)*100 -> 0 | M45: =(K45/I45)*1 -> 0 | N45: =IF(E45>5,5000,IF(E45 >4,3000,IF(E45>3,1500,IF(E45>2,800,IF(E45>1,400,100))))) -> 100 | O45: =IF(M45>=$P$10,M45," ") | P45: =IF(AND(M45<$P$10,M45>=$P$11),M45," ") | Q45: =IF(M45<$P$11,M45," ") -> 0 | R45: =MAX(1,M45)-M45 -> 1
...

Sheet RAW SCORE
C3: TEAM ALPHA | E3: RESULT | F3: 10 | G3: 10 | H3: 10 | I3: 10 | K3: 10 | L3: 10 | M3: 10 | O3: 10 | P3: 10 | S3: 0.3 | T3: 0.7 | U3: 1
D4: =R4 -> 0 | E4: =U4 -> 0 | J4: =SUM(F4:I4) -> 0 | N4: =SUM(K4:M4) -> 0 | Q4: =SUM(O4:P4) -> 0 | R4: =J4+(2*N4)+Q4 -> 0 | S4: =(R4/100)*30 -> 0 | U4: =S4+T4 -> 0
D5: =R5 -> 0 | E5: =U5 -> 0 | J5: =SUM(F5:I5) -> 0 | N5: =SUM(K5:M5) -> 0 | Q5: =SUM(O5:P5) -> 0 | R5: =J5+(2*N5)+Q5 -> 0 | S5: =(R5/100)*30 -> 0 | U5: =S5+T5 -> 0
D6: =R6 -> 0 | E6: =U6 -> 0 | J6: =SUM(F6:I6) -> 0 | N6: =SUM(K6:M6) -> 0 | Q6: =SUM(O6:P6) -> 0 | R6: =J6+(2*N6)+Q6 -> 0 | S6: =(R6/100)*30 -> 0 | U6: =S6+T6 -> 0
D7: =R7 -> 0 | E7: =U7 -> 0 | J7: =SUM(F7:I7) -> 0 | N7: =SUM(K7:M7) -> 0 | Q7: =SUM(O7:P7) -> 0 | R7: =J7+(2*N7)+Q7 -> 0 | S7: =(R7/100)*30 -> 0 | U7: =S7+T7 -> 0
D8: =R8 -> 0 | E8: =U8 -> 0 | J8: =SUM(F8:I8) -> 0 | N8: =SUM(K8:M8) -> 0 | Q8: =SUM(O8:P8) -> 0 | R8: =J8+(2*N8)+Q8 -> 0 | S8: =(R8/100)*30 -> 0 | U8: =S8+T8 -> 0
D9: =R9 -> 0 | E9: =U9 -> 0 | J9: =SUM(F9:I9) -> 0 | N9: =SUM(K9:M9) -> 0 | Q9: =SUM(O9:P9) -> 0 | R9: =J9+(2*N9)+Q9 -> 0 | S9: =(R9/100)*30 -> 0 | U9: =S9+T9 -> 0
D10: =R10 -> 0 | E10: =U10 -> 0 | J10: =SUM(F10:I10) -> 0 | N10: =SUM(K10:M10) -> 0 | Q10: =SUM(O10:P10) -> 0 | R10: =J10+(2*N10)+Q10 -> 0 | S10: =(R10/100)*30 -> 0 | U10: =S10+T10 -> 0
D11: =R11 -> 0 | E11: =U11 -> 0 | J11: =SUM(F11:I11) -> 0 | N11: =SUM(K11:M11) -> 0 | Q11: =SUM(O11:P11) -> 0 | R11: =J11+(2*N11)+Q11 -> 0 | S11: =(R11/100)*30 -> 0 | U11: =S11+T11 -> 0
D12: =R12 -> 0 | E12: =U12 -> 0 | J12: =SUM(F12:I12) -> 0 | N12: =SUM(K12:M12) -> 0 | Q12: =SUM(O12:P12) -> 0 | R12: =J12+(2*N12)+Q12 -> 0 | S12: =(R12/100)*30 -> 0 | U12: =S12+T12 -> 0
C13: TEAM BETA | D13: =R13 -> 0 | E13: =U13 -> 0 | J13: =SUM(F13:I13) -> 0 | N13: =SUM(K13:M13) -> 0 | Q13: =SUM(O13:P13) -> 0 | R13: =J13+(2*N13)+Q13 -> 0 | S13: =(R13/100)*30 -> 0 | U13: =S13+T13 -> 0
D14: =R14 -> 0 | E14: =U14 -> 0 | J14: =SUM(F14:I14) -> 0 | N14: =SUM(K14:M14) -> 0 | Q14: =SUM(O14:P14) -> 0 | R14: =J14+(2*N14)+Q14 -> 0 | S14: =(R14/100)*30 -> 0 | U14: =S14+T14 -> 0
D15: =R15 -> 0 | E15: =U15 -> 0 | J15: =SUM(F15:I15) -> 0 | N15: =SUM(K15:M15) -> 0 | Q15: =SUM(O15:P15) -> 0 | R15: =J15+(2*N15)+Q15 -> 0 | S15: =(R15/100)*30 -> 0 | U15: =S15+T15 -> 0
D16: =R16 -> 0 | E16: =U16 -> 0 | J16: =SUM(F16:I16) -> 0 | N16: =SUM(K16:M16) -> 0 | Q16: =SUM(O16:P16) -> 0 | R16: =J16+(2*N16)+Q16 -> 0 | S16: =(R16/100)*30 -> 0 | U16: =S16+T16 -> 0
D17: =R17 -> 0 | E17: =U17 -> 0 | J17: =SUM(F17:I17) -> 0 | N17: =SUM(K17:M17) -> 0 | Q17: =SUM(O17:P17) -> 0 | R17: =J17+(2*N17)+Q17 -> 0 | S17: =(R17/100)*30 -> 0 | U17: =S17+T17 -> 0
D18: =R18 -> 0 | E18: =U18 -> 0 | J18: =SUM(F18:I18) -> 0 | N18: =SUM(K18:M18) -> 0 | Q18: =SUM(O18:P18) -> 0 | R18: =J18+(2*N18)+Q18 -> 0 | S18: =(R18/100)*30 -> 0 | U18: =S18+T18 -> 0
D19: =R19 -> 0 | E19: =U19 -> 0 | J19: =SUM(F19:I19) -> 0 | N19: =SUM(K19:M19) -> 0 | Q19: =SUM(O19:P19) -> 0 | R19: =J19+(2*N19)+Q19 -> 0 | S19: =(R19/100)*30 -> 0 | U19: =S19+T19 -> 0
D20: =R20 -> 0 | E20: =U20 -> 0 | J20: =SUM(F20:I20) -> 0 | N20: =SUM(K20:M20) -> 0 | Q20: =SUM(O20:P20) -> 0 | R20: =J20+(2*N20)+Q20 -> 0 | S20: =(R20/100)*30 -> 0 | U20: =S20+T20 -> 0
D21: =R21 -> 0 | E21: =U21 -> 0 | J21: =SUM(F21:I21) -> 0 | N21: =SUM(K21:M21) -> 0 | Q21: =SUM(O21:P21) -> 0 | R21: =J21+(2*N21)+Q21 -> 0 | S21: =(R21/100)*30 -> 0 | U21: =S21+T21 -> 0
D22: =R22 -> 0 | E22: =U22 -> 0 | J22: =SUM(F22:I22) -> 0 | N22: =SUM(K22:M22) -> 0 | Q22: =SUM(O22:P22) -> 0 | R22: =J22+(2*N22)+Q22 -> 0 | S22: =(R22/100)*30 -> 0 | U22: =S22+T22 -> 0
C23: TEAM GAMMA | D23: =R23 -> 0 | E23: =U23 -> 0 | J23: =SUM(F23:I23) -> 0 | N23: =SUM(K23:M23) -> 0 | Q23: =SUM(O23:P23) -> 0 | R23: =J23+(2*N23)+Q23 -> 0 | S23: =(R23/100)*30 -> 0 | U23: =S23+T23 -> 0
D24: =R24 -> 0 | E24: =U24 -> 0 | J24: =SUM(F24:I24) -> 0 | N24: =SUM(K24:M24) -> 0 | Q24: =SUM(O24:P24) -> 0 | R24: =J24+(2*N24)+Q24 -> 0 | S24: =(R24/100)*30 -> 0 | U24: =S24+T24 -> 0
D25: =R25 -> 0 | E25: =U25 -> 0 | J25: =SUM(F25:I25) -> 0 | N25: =SUM(K25:M25) -> 0 | Q25: =SUM(O25:P25) -> 0 | R25: =J25+(2*N25)+Q25 -> 0 | S25: =(R25/100)*30 -> 0 | U25: =S25+T25 -> 0
D26: =R26 -> 0 | E26: =U26 -> 0 | J26: =SUM(F26:I26) -> 0 | N26: =SUM(K26:M26) -> 0 | Q26: =SUM(O26:P26) -> 0 | R26: =J26+(2*N26)+Q26 -> 0 | S26: =(R26/100)*30 -> 0 | U26: =S26+T26 -> 0
D27: =R27 -> 0 | E27: =U27 -> 0 | J27: =SUM(F27:I27) -> 0 | N27: =SUM(K27:M27) -> 0 | Q27: =SUM(O27:P27) -> 0 | R27: =J27+(2*N27)+Q27 -> 0 | S27: =(R27/100)*30 -> 0 | U27: =S27+T27 -> 0
D28: =R28 -> 0 | E28: =U28 -> 0 | J28: =SUM(F28:I28) -> 0 | N28: =SUM(K28:M28) -> 0 | Q28: =SUM(O28:P28) -> 0 | R28: =J28+(2*N28)+Q28 -> 0 | S28: =(R28/100)*30 -> 0 | U28: =S28+T28 -> 0
D29: =R29 -> 0 | E29: =U29 -> 0 | J29: =SUM(F29:I29) -> 0 | N29: =SUM(K29:M29) -> 0 | Q29: =SUM(O29:P29) -> 0 | R29: =J29+(2*N29)+Q29 -> 0 | S29: =(R29/100)*30 -> 0 | U29: =S29+T29 -> 0
D30: =R30 -> 0 | E30: =U30 -> 0 | J30: =SUM(F30:I30) -> 0 | N30: =SUM(K30:M30) -> 0 | Q30: =SUM(O30:P30) -> 0 | R30: =J30+(2*N30)+Q30 -> 0 | S30: =(R30/100)*30 -> 0 | U30: =S30+T30 -> 0
D31: =R31 -> 0 | E31: =U31 -> 0 | J31: =SUM(F31:I31) -> 0 | N31: =SUM(K31:M31) -> 0 | Q31: =SUM(O31:P31) -> 0 | R31: =J31+(2*N31)+Q31 -> 0 | S31: =(R31/100)*30 -> 0 | U31: =S31+T31 -> 0
D32: =R32 -> 0 | E32: =U32 -> 0 | J32: =SUM(F32:I32) -> 0 | N32: =SUM(K32:M32) -> 0 | Q32: =SUM(O32:P32) -> 0 | R32: =J32+(2*N32)+Q32 -> 0 | S32: =(R32/100)*30 -> 0 | U32: =S32+T32 -> 0
C33: TEAM DELTA | D33: =R33 -> 0 | E33: =U33 -> 0 | J33: =SUM(F33:I33) -> 0 | N33: =SUM(K33:M33) -> 0 | Q33: =SUM(O33:P33) -> 0 | R33: =J33+(2*N33)+Q33 -> 0 | S33: =(R33/100)*30 -> 0 | U33: =S33+T33 -> 0
D34: =R34 -> 0 | E34: =U34 -> 0 | J34: =SUM(F34:I34) -> 0 | N34: =SUM(K34:M34) -> 0 | Q34: =SUM(O34:P34) -> 0 | R34: =J34+(2*N34)+Q34 -> 0 | S34: =(R34/100)*30 -> 0 | U34: =S34+T34 -> 0
D35: =R35 -> 0 | E35: =U35 -> 0 | J35: =SUM(F35:I35) -> 0 | N35: =SUM(K35:M35) -> 0 | Q35: =SUM(O35:P35) -> 0 | R35: =J35+(2*N35)+Q35 -> 0 | S35: =(R35/100)*30 -> 0 | U35: =S35+T35 -> 0
D36: =R36 -> 0 | E36: =U36 -> 0 | J36: =SUM(F36:I36) -> 0 | N36: =SUM(K36:M36) -> 0 | Q36: =SUM(O36:P36) -> 0 | R36: =J36+(2*N36)+Q36 -> 0 | S36: =(R36/100)*30 -> 0 | U36: =S36+T36 -> 0
D37: =R37 -> 0 | E37: =U37 -> 0 | J37: =SUM(F37:I37) -> 0 | N37: =SUM(K37:M37) -> 0 | Q37: =SUM(O37:P37) -> 0 | R37: =J37+(2*N37)+Q37 -> 0 | S37: =(R37/100)*30 -> 0 | U37: =S37+T37 -> 0
D38: =R38 -> 0 | E38: =U38 -> 0 | J38: =SUM(F38:I38) -> 0 | N38: =SUM(K38:M38) -> 0 | Q38: =SUM(O38:P38) -> 0 | R38: =J38+(2*N38)+Q38 -> 0 | S38: =(R38/100)*30 -> 0 | U38: =S38+T38 -> 0
D39: =R39 -> 0 | E39: =U39 -> 0 | J39: =SUM(F39:I39) -> 0 | N39: =SUM(K39:M39) -> 0 | Q39: =SUM(O39:P39) -> 0 | R39: =J39+(2*N39)+Q39 -> 0 | S39: =(R39/100)*30 -> 0 | U39: =S39+T39 -> 0
D40: =R40 -> 0 | E40: =U40 -> 0 | J40: =SUM(F40:I40) -> 0 | N40: =SUM(K40:M40) -> 0 | Q40: =SUM(O40:P40) -> 0 | R40: =J40+(2*N40)+Q40 -> 0 | S40: =(R40/100)*30 -> 0 | U40: =S40+T40 -> 0
D41: =R41 -> 0 | E41: =U41 -> 0 | J41: =SUM(F41:I41) -> 0 | N41: =SUM(K41:M41) -> 0 | Q41: =SUM(O41:P41) -> 0 | R41: =J41+(2*N41)+Q41 -> 0 | S41: =(R41/100)*30 -> 0 | U41: =S41+T41 -> 0
D42: =R42 -> 0 | E42: =U42 -> 0 | J42: =SUM(F42:I42) -> 0 | N42: =SUM(K42:M42) -> 0 | Q42: =SUM(O42:P42) -> 0 | R42: =J42+(2*N42)+Q42 -> 0 | S42: =(R42/100)*30 -> 0 | U42: =S42+T42 -> 0
...

Sheet Chart Data
B2: CHART DATA
B4: =MIN(1,1-B5) -> #REF!
B5: =MIN(TotalMonthlyExpenses/TotalMonthlyIncome,1) -> #REF!
B6: =(TotalMonthlyExpenses/TotalMonthlyIncome)>1 -> #REF!
